2018-10-20 11:06:02,823 - cmdb - ERROR:  Traceback (most recent call last):
  File "D:\m1\auto_client\src\plugins\disk.py", line 23, in linux
    output = open(os.path.join(self.base_dir,'fles/disk.out'), 'r').read()
FileNotFoundError: [Errno 2] No such file or directory: 'D:\\m1\\auto_client\\fles/disk.out'

